<?xml version="1.0"?>

<robot name="myfirstrobot">

<link name="base_link">
    <inertial>
        <origin xyz="0 0 0.1" />
        <mass value="1000.0" />
        <inertia ixx="1.0" ixy="0.0" ixz="0.0"
        iyy="1.0" iyz="0.0" izz="1.0" />
    </inertial>
    <visual>
        <origin xyz="0 0 0.1"/>
        <geometry>
            <box size="0.5 0.5 0.3"/>
        </geometry>
    </visual>
    <collision>
     <origin xyz="0 0 0.1"/>
      <geometry>
        <box size="0.5 0.5 0.3"/>
      </geometry>
    </collision>
</link>

<material name="blue">
    <color rgba="0 0 0.8 1"/>
</material>

<link name="body_link">
    <inertial>
        <origin xyz="0 0 0.5" />
        <mass value="1.0" />
        <inertia ixx="1.0" ixy="0.0" ixz="0.0"
        iyy="1.0" iyz="0.0" izz="1.0" />
    </inertial>
    <visual>
        <origin rpy="0 0 0" xyz="0 0 0.5"/>
        <geometry>
            <box size="0.1 0.1 1"/>
        </geometry>
        <material name="blue"/>
    </visual>
    <collision>
     <origin xyz="0 0 0.5"/>
      <geometry>
        <box size="0.1 0.1 1"/>
      </geometry>
    </collision>
</link>

<joint name="base_to_body_link" type="revolute">
    <parent link="base_link"/>
    <child link="body_link"/>
    <dynamics damping="0.0" friction="0.0001"/>
    <origin xyz="0 0 0.1"/>
    <axis xyz = "1 0 0"/>
    <limit lower="0" upper="0" effort="10.0" velocity="0.0"/>
</joint>

<link name="top_link">
    <inertial>
        <origin xyz="0.2 0 0" />
        <mass value="1.0" />
        <inertia ixx="0.83" ixy="0.0" ixz="0.0"
        iyy="0" iyz="0.0" izz="0.83" />
    </inertial>

    <visual>
        <origin rpy="0 0 0" xyz="0.2 0 0"/>
        <geometry>
            <box size="0.5 0.1 0.1"/>
        </geometry>
        <material name="blue"/>
    </visual>

    <collision>
     <origin xyz="0.2 0 0"/>
      <geometry>
        <box size="0.5 0.1 0.1"/>
      </geometry>
    </collision>
</link>

<joint name="body_to_top_link" type="continuous">
    <parent link="body_link"/>
    <child link="top_link"/>
    <dynamics damping="0.0" friction="0.0001"/>
    <origin xyz="0 0 1"/>
    <axis xyz = "0 0 1"/>
    <limit lower="-3.14" upper="3.14" effort="10.0" velocity="0.5"/>
</joint>
</robot>